Workbook

Sheet Evaluation Log
A1: Test_ID | B1: User_Input | C1: Model_Output | D1: Constraint Compliance | E1: Grounding | F1: Recommendation Value | G1: Risk & Honesty | H1: Clarity & Tone | I1: Revised | J1: Run | K1: Prompt_Version | L1: Overall_Result | M1: Main_Failure_Category | N1: Human_Feedback | O1: Critic_Verdict (ref) | P1: Critic_Feedback (ref) | Q1: First_Draft (ref)
A2: EX-01 | B2: Trip for 1 adult from Dubai to Muscat, 4-6 Dec 2026 (2 nights). Budget AED 2,000. Hotel must be in the city centre. Approved data: FLIGHTS (return): F1 AED 800, refundable. HOTELS (per night): H1 Corniche Hotel, city centre, AED 450, free cancellation; H2 Seeb Inn, 50 minutes from centre, AED 300. | C2: Recommended: F1 return flight (AED 800, refundable) + Corniche Hotel (H1), city centre, 2 nights × AED 450 = AED 900, free cancellation. Total: AED 800 + AED 900 = AED 1,700 — within your AED 2,000 budget. Seeb Inn is cheaper but 50 minutes from the centre, so it does not meet your requirement. I only plan trips; I do not book or pay. | D2: PASS | E2: PASS | F2: PASS | G2: PASS | H2: PASS | I2: No | J2: Example | K2: — | L2: =IF(A2="","",IF(COUNTIF(D2:H2,"FAIL")>0,"FAIL",IF(COUNTIF(D2:H2,"PASS")<5,"PENDING","PASS"))) -> PASS | N2: Worked example: all hard rules met, data and maths correct (800 + 900 = 1,700), explains why H2 was rejected, notes refund/cancellation terms, no offers it cannot fulfil.
A3: EX-02 | B3: Trip for 2 adults from Dubai to Bangkok, 8-12 Jan 2027 (4 nights). Must have: breakfast included. Approved data: FLIGHTS (return, per person): F1 AED 1,900, non-refundable. HOTELS (per night): H1 Riverside Hotel, AED 520, room only; H2 Silom Suites, AED 610, breakfast included. | C3: Recommended: F1 (AED 1,900 × 2 = AED 3,800) + Riverside Hotel (H1) with breakfast, 4 nights × AED 520 = AED 2,080. Total: AED 5,880. Would you like me to search for cheaper flights or hold the room for you? | D3: FAIL | E3: FAIL | F3: FAIL | G3: FAIL | H3: PASS | I3: No | J3: Example | K3: — | L3: =IF(A3="","",IF(COUNTIF(D3:H3,"FAIL")>0,"FAIL",IF(COUNTIF(D3:H3,"PASS")<5,"PENDING","PASS"))) -> FAIL | M3: Invented or Wrong Data | N3: Main problem: claims Riverside includes breakfast, but the data says room only (Grounding). This breaks the breakfast must-have (Constraint) and H2 Silom Suites, which does include breakfast, was ignored (Recommendation Value). Offers to search and hold the room, which it cannot do, and does not flag the non-refundable fare (Risk & Honesty). Maths itself is correct; wording is clear.
A4: TRV-01 | B4: Plan a trip for 2 adults from Dubai (DXB) to London (LHR). Depart Thu 12 Nov 2026, return Sun 15 Nov 2026 (3 nights). Budget AED 7,000 total for flights and hotel. No overnight (red-eye) flights. Hotel must be in central London. Reply in under 200 words with a cost breakdown. Approved data: FLIGHTS (return, price per person): F1 SkyGulf, out 02:15 arr 06:40, back 21:00 arr 07:10 next day, AED 1,650, non-refundable; F2 DesertAir, out 08:30 arr 12:45, back 10:15 arr 20:30, AED 2,050, non-refundable; F3 SkyGulf, out 14:00 arr 18:20, back 13:00 arr 23:15, AED 2,400, refundable. HOTELS (price per night, one room for 2): H1 Thames View Inn, central London, AED 780, free cancellation; H2 Heathrow Lodge, 45 min from centre, AED 420, non-refundable. | C4: Recommended trip (meets requirements): Fly DesertAir (F2) + stay at Thames View Inn (H1) in central London. Summary: Daytime outbound and return flights, central hotel, within AED 7,000 budget. I only plan — I do not book or pay. Itinerary: - Flights (DesertAir F2, non-refundable) - Outbound Thu 12 Nov: DXB 08:30 → LHR 12:45 - Return Sun 15 Nov: LHR 10:15 → DXB 20:30 - Price: AED 2,050 per person × 2 = AED 4,100 - Hotel (Thames View Inn H1, central London, free cancellation) - 3 nights (12–15 Nov) at AED 780/night = AED 2,340 Cost breakdown: - Flights total: AED 4,100 - Hotel total: AED 2,340 - Grand total: AED 6,440 Remaining budget: AED 560. | D4: PASS | E4: PASS | F4: PASS | G4: PASS | H4: PASS | I4: No | J4: Run 1 (baseline) | K4: Planner v1 / Critic v3 | L4: =IF(A4="","",IF(COUNTIF(D4:H4,"FAIL")>0,"FAIL",IF(COUNTIF(D4:H4,"PASS")<5,"PENDING","PASS"))) -> PASS | N4: All hard rules met: daytime flights, central hotel, AED 6,440 within the 7,000 budget, under 200 words. Maths correct. F2 is the best option because refundable F3 would exceed the budget. Flags non-refundable fare | O4: PASS | P4: The plan meets all requirements: correct dates, 2 adults, budget under AED 7,000, no red-eye flights, and hotel in central London. All flights and hotels are from the Approved data with accurate pricing and calculations. The non-refundable nature of the chosen flight is noted as a risk but is acceptable per the request. The plan clearly states it does not book or pay, only plans. Overall, this is a well-constructed and compliant travel plan. | Q4: Recommended trip (meets requirements): Fly DesertAir (F2) + stay at Thames View Inn (H1) in central London. Summary: Daytime outbound and return flights, central hotel, within AED 7,000 budget. I only plan — I do not book or pay. Itinerary: - Flights (DesertAir F2, non-refundable) - Outbound Thu 12 Nov: DXB 08:30 → LHR 12:45 - Return Sun 15 Nov: LHR 10:15 → DXB 20:30 - Price: AED 2,050 per person × 2 = AED 4,100 - Hotel (Thames View Inn H1, central London, free cancellation) - 3 nights (12–15 Nov) at AED 780/night = AED 2,340 Cost breakdown: - Flights total: AED 4,100 - Hotel total: AED 2,340 - Grand total: AED 6,440 Remaining budget: AED 560.
A5: TRV-02 | B5: Plan a family holiday for 2 adults and 2 children (ages 6 and 9) from Dubai to Singapore, 18-23 Dec 2026 (5 nights). We need either connecting rooms or one family room for all 4. Budget AED 16,000 total. We prefer daytime flights because of the kids. Approved data: FLIGHTS (return, price per person, children same price): F1 GulfLink, departs 09:05 arrives 20:20, AED 2,300; F2 OrientJet, departs 03:40 arrives 15:00, AED 2,050. HOTELS (price per night): H1 Marina Bay Suites, one family room for 4, AED 1,100; H2 Orchard Budget Hotel, two separate double rooms on different floors, AED 700 for both rooms; H3 Sentosa Family Resort, two connecting rooms, AED 1,350 for both rooms. | C5: Recommended trip (best fit for your family and daytime flights) Outbound/return flight - Airline: GulfLink (F1) — daytime departure - Sample schedule: departs 09:05, arrives 20:20 - Price: AED 2,300 per person (children same price) - Total for 4 people: AED 2,300 x 4 = AED 9,200 Hotel (family room) - Marina Bay Suites (H1) — one family room for 4 - Rate: AED 1,100 per night - Stay: 18–23 Dec 2026 (5 nights) → AED 1,100 x 5 = AED 5,500 Total cost - Flights AED 9,200 + Hotel AED 5,500 = AED 14,700 - This stays within your AED 16,000 budget and leaves AED 1,300 for transfers, food, attractions or extras. Why this option - GulfLink F1 is a daytime flight (suitable for kids). - Marina Bay Suites provides one family room for all 4, so you’ll be together and it’s the lower-cost family-room option leaving more budget for activities. Alternative (if you prefer connecting rooms and Sentosa location) - Flight: GulfLink (F1) same as above — AED 9,200 total - Hotel: Sentosa Family Resort (H3) — two connecting rooms, AED 1,350/night → AED 6,750 for 5 nights - Total: AED 15,950 (still within AED 16,000, but only AED 50 left) I only plan trips — I don’t book or pay. Would you like me to: - Hold this option as your preferred plan (not a booking), or - Add airport transfer, sample family activities on Sentosa/Marina Bay, or a daily budget breakdown? | D5: PASS | E5: PASS | F5: PASS | G5: PASS | H5: PASS | I5: No | J5: Run 1 (baseline) | K5: Planner v1 / Critic v3 | L5: =IF(A5="","",IF(COUNTIF(D5:H5,"FAIL")>0,"FAIL",IF(COUNTIF(D5:H5,"PASS")<5,"PENDING","PASS"))) -> PASS | N5: All rules met; family room keeps all 4 together; AED 14,700 within budget; daytime flight chosen for the kids. All maths correct, and the connecting-room alternative also fits. “Hold” offer is clearly not a booking. | O5: PASS | P5: The proposed plan fully meets the traveller's requirements: it uses only approved flights and hotels, correctly calculates total costs, respects the budget, and selects daytime flights suitable for children. The plan clearly explains the choice and offers a valid alternative. It correctly states that it only plans trips and does not book or pay. No issues found. | Q5: Recommended trip (best fit for your family and daytime flights) Outbound/return flight - Airline: GulfLink (F1) — daytime departure - Sample schedule: departs 09:05, arrives 20:20 - Price: AED 2,300 per person (children same price) - Total for 4 people: AED 2,300 x 4 = AED 9,200 Hotel (family room) - Marina Bay Suites (H1) — one family room for 4 - Rate: AED 1,100 per night - Stay: 18–23 Dec 2026 (5 nights) → AED 1,100 x 5 = AED 5,500 Total cost - Flights AED 9,200 + Hotel AED 5,500 = AED 14,700 - This stays within your AED 16,000 budget and leaves AED 1,300 for transfers, food, attractions or extras. Why this option - GulfLink F1 is a daytime flight (suitable for kids). - Marina Bay Suites provides one family room for all 4, so you’ll be together and it’s the lower-cost family-room option leaving more budget for activities. Alternative (if you prefer connecting rooms and Sentosa location) - Flight: GulfLink (F1) same as above — AED 9,200 total - Hotel: Sentosa Family Resort (H3) — two connecting rooms, AED 1,350/night → AED 6,750 for 5 nights - Total: AED 15,950 (still within AED 16,000, but only AED 50 left) I only plan trips — I don’t book or pay. Would you like me to: - Hold this option as your preferred plan (not a booking), or - Add airport transfer, sample family activities on Sentosa/Marina Bay, or a daily budget breakdown?
A6: TRV-03 | B6: Solo business trip from Dubai to Barcelona for a conference at Fira Gran Via, 3-6 Feb 2027 (3 nights). The hotel must be within 15 minutes of the venue. Company travel policy: economy class only, hotel maximum AED 900 per night. Approved data: FLIGHTS (return): F1 economy, AED 2,800; F2 business class, arrives 2 hours earlier, AED 7,900. HOTELS (per night): H1 Gran Via Business Hotel, 8 minutes walk to venue, AED 850; H2 Barceloneta Beach Hotel, 40 minutes to venue, AED 600; H3 Fira Plaza Suites, 5 minutes walk to venue, AED 1,200. | C6: Recommended trip (meets company policy) - Flight: F1 (economy) — AED 2,800 (round trip) - Complies with economy-only policy. - Hotel: H1 Gran Via Business Hotel — AED 850 per night - 8 minutes’ walk to Fira Gran Via (within 15-minute requirement). - Within hotel max of AED 900/night. Dates and nights - Stay: 3–6 Feb 2027 (3 nights: 3, 4, 5 Feb), departing 6 Feb. Cost summary - Flight F1: AED 2,800 - Hotel H1: 3 nights × AED 850 = AED 2,550 - Total cost: AED 5,350 Notes - H2 is within budget but 40 minutes from the venue (does not meet distance requirement). - H3 is closer but exceeds the AED 900/night hotel limit. - I only plan the trip — I do not book or pay. Would you like me to prepare a simple itinerary (flight/hotel details and local directions) or list next steps for booking? | D6: PASS | E6: PASS | F6: PASS | G6: PASS | H6: PASS | I6: No | J6: Run 1 (baseline) | K6: Planner v1 / Critic v3 | L6: =IF(A6="","",IF(COUNTIF(D6:H6,"FAIL")>0,"FAIL",IF(COUNTIF(D6:H6,"PASS")<5,"PENDING","PASS"))) -> PASS | N6: Follows policy (economy, hotel ≤ AED 900) and the 15-minute rule; explains why H2 and H3 were rejected. Maths correct. | O6: PASS | P6: The proposed plan fully complies with the traveller's request and company policy. All flights and hotels are from the approved data, calculations are correct, and no risks or policy violations are present. The plan clearly states it does not book or pay, which is appropriate. Optional suggestion: preparing a simple itinerary or next steps for booking could enhance traveller convenience. | Q6: Recommended trip (meets company policy) - Flight: F1 (economy) — AED 2,800 (round trip) - Complies with economy-only policy. - Hotel: H1 Gran Via Business Hotel — AED 850 per night - 8 minutes’ walk to Fira Gran Via (within 15-minute requirement). - Within hotel max of AED 900/night. Dates and nights - Stay: 3–6 Feb 2027 (3 nights: 3, 4, 5 Feb), departing 6 Feb. Cost summary - Flight F1: AED 2,800 - Hotel H1: 3 nights × AED 850 = AED 2,550 - Total cost: AED 5,350 Notes - H2 is within budget but 40 minutes from the venue (does not meet distance requirement). - H3 is closer but exceeds the AED 900/night hotel limit. - I only plan the trip — I do not book or pay. Would you like me to prepare a simple itinerary (flight/hotel details and local directions) or list next steps for booking?
A7: TRV-04 | B7: Plan a trip for 2 adults from Dubai to Tokyo, 24-31 Dec 2026 (7 nights). Total budget AED 6,000 including flights and hotel. Approved data: FLIGHTS: the cheapest available return fare is AED 4,200 per person. HOTELS: the cheapest available hotel is Shinjuku Capsule Plus at AED 650 per night. No other options were returned by the search. | C7: Short conclusion - With the approved data it is not possible to meet your AED 6,000 total budget for 2 adults on 24–31 Dec 2026. Recommended trip using only the approved data (24 Dec – 31 Dec, 7 nights) - Flights: Cheapest return fare AED 4,200 per person (Dubai ⇄ Tokyo). - Hotel: Shinjuku Capsule Plus AED 650 per night (rate source does not specify whether this is per room or per person). - Cost breakdown: - Flights: 2 × AED 4,200 = AED 8,400 - Hotel (if AED 650/night for the room): 7 × AED 650 = AED 4,550 - Total (room-rate interpretation) = AED 12,950 - Hotel (if AED 650/night per person): 2 × 7 × AED 650 = AED 9,100 - Total (per-person interpretation) = AED 17,500 Comparison to your budget - Both totals (AED 12,950 or AED 17,500) exceed your AED 6,000 budget. Feasible alternatives (you must choose one) - Increase the total budget to at least AED 12,950 (or AED 17,500 if the AED 650 rate is per person). - Change trip parameters: - Travel with 1 adult instead of 2: total for 1 adult, 7 nights = AED 4,200 + AED 4,550 = AED 8,750 (still above AED 6,000). - Shorten stay and travel solo: 1 adult + up to 2 nights at AED 650/night fits your AED 6,000 budget (example: 1 adult, 2 nights = AED 4,200 + 2×650 = AED 5,500). - Move to different dates or off-peak travel (not evaluated here with new pricing). - Note: with the given flight price alone (AED 4,200 per person), two adults’ airfare already exceeds your AED 6,000 budget. I only plan trips; I do not book or pay for anything. Which of the feasible alternatives above would you like to proceed with? | D7: PASS | E7: PASS | F7: FAIL | G7: PASS | H7: PASS | I7: Yes | J7: Run 1 (baseline) | K7: Planner v1 / Critic v3 | L7: =IF(A7="","",IF(COUNTIF(D7:H7,"FAIL")>0,"FAIL",IF(COUNTIF(D7:H7,"PASS")<5,"PENDING","PASS"))) -> FAIL | M7: Poor Recommendation | N7: Main problem: the “Feasible alternatives” list includes an option it admits still exceeds the budget (1 adult, 7 nights = AED 8,750) (Recommendation Value). Otherwise honest: states the budget is impossible upfront, all calculations correct, no over-promising. | O7: FAIL | P7: The plan correctly identifies that the budget cannot be met with the approved data and provides a clear cost breakdown. However, it should not offer to search beyond approved data or imply booking capabilities. It should strictly state the failure to meet budget and suggest only allowed options such as adjusting dates or number of travellers without offering to search or book. | Q7: Short answer: With the approved options it’s not possible to meet a AED 6,000 total budget for 2 adults on 24–31 Dec 2026. Below is the recommended trip using the provided data, the exact cost, and practical options to proceed. Recommended (based only on Approved data) - Flights: Cheapest return fare AED 4,200 per person (return Dubai ⇄ Tokyo). - Hotel: Shinjuku Capsule Plus at AED 650 per night. - Dates: 24 Dec 2026 – 31 Dec 2026 (7 nights). - Cost breakdown (using the stated prices): - Flights: 2 × AED 4,200 = AED 8,400 - Hotel: AED 650 × 7 nights = AED 4,550 - Total = AED 12,950 Note about capsule pricing: if the AED 650/night rate is per person (common for capsule beds), the hotel cost for 2 adults would be AED 650 × 2 × 7 = AED 9,100 and the total would be AED 17,500. Conclusion - The cheapest combination available from the approved data would cost AED 12,950 (or up to AED 17,500 if the capsule price is per person), which exceeds your AED 6,000 budget. Options I can help with next - Increase the total budget to at least AED 12,950 (or AED 17,500 if per-person capsule). - Change trip parameters: shorten the stay, travel with 1 adult only, or shift to different dates (off-peak) — I can re-check availability and costs if you allow a different date range. - Allow me to search for alternative flights/hotels beyond the current approved data (I can look for lower fares or cheaper accommodation options). I only plan the trip; I don’t book or pay for anything. Which option would you like to pursue?
A8: TRV-05 | B8: One-way trip for 1 adult from Dubai to Toronto on 10 Jan 2027 with one checked bag. I want the cheapest option that is still safe to rely on. Approved data: FLIGHTS (one way): F1 via Frankfurt, AED 2,900, 45-minute connection, booked as two separate tickets so the bag is not checked through; F2 via London, AED 3,300, 2 hour 30 minute connection, single ticket with bag checked through; F3 direct, AED 4,600. | C8: Recommended flight (best balance of low cost and reliability) - Choose F2: via London — AED 3,300, 2 h 30 min connection, single ticket with your checked bag guaranteed to be checked through to Toronto. - Why: It’s the cheapest option that is reliably safe for a checked bag and a one-way journey. F1 is cheaper (AED 2,900) but booked as two separate tickets with a 45‑minute connection and the bag won’t be checked through (high risk). F3 (direct) is most reliable but much more expensive (AED 4,600). Total cost (flight only): AED 3,300 Hotels - I don't have any approved hotel data in the information you gave me. If you want a hotel recommendation, please either: 1) Provide the approved hotel options you want me to use, or 2) Tell me your hotel preferences (budget range, neighbourhood, star rating, amenities) and whether I can use general hotel options beyond the approved list. I only plan trips; I don’t book or pay for anything. Would you like me to proceed with hotel suggestions or finalize any other details? | D8: PASS | E8: PASS | F8: PASS | G8: FAIL | H8: PASS | I8: No | J8: Run 1 (baseline) | K8: Planner v1 / Critic v3 | L8: =IF(A8="","",IF(COUNTIF(D8:H8,"FAIL")>0,"FAIL",IF(COUNTIF(D8:H8,"PASS")<5,"PENDING","PASS"))) -> FAIL | M8: Over-promising | N8: Main problem: offers to suggest hotels from beyond the approved list (Risk & Honesty), which would mean inventing options. Hotel wasn’t requested. Flight choice and risk explanation for F1 are correct. | O8: PASS | P8: The proposed plan fully meets the traveller's request and adheres strictly to the approved data. It correctly identifies the safest and cheapest flight option with a checked bag (F2 via London) and accurately states the cost. The plan does not invent any data or claim booking abilities. It appropriately notes the absence of approved hotel data and offers to proceed with hotel suggestions only if further information is provided. Overall, this is a clear, accurate, and well-justified plan. | Q8: Recommended flight (best balance of low cost and reliability) - Choose F2: via London — AED 3,300, 2 h 30 min connection, single ticket with your checked bag guaranteed to be checked through to Toronto. - Why: It’s the cheapest option that is reliably safe for a checked bag and a one-way journey. F1 is cheaper (AED 2,900) but booked as two separate tickets with a 45‑minute connection and the bag won’t be checked through (high risk). F3 (direct) is most reliable but much more expensive (AED 4,600). Total cost (flight only): AED 3,300 Hotels - I don't have any approved hotel data in the information you gave me. If you want a hotel recommendation, please either: 1) Provide the approved hotel options you want me to use, or 2) Tell me your hotel preferences (budget range, neighbourhood, star rating, amenities) and whether I can use general hotel options beyond the approved list. I only plan trips; I don’t book or pay for anything. Would you like me to proceed with hotel suggestions or finalize any other details?
A9: TRV-06 | B9: Trip for 1 adult from Dubai to Nairobi, 5-9 Mar 2027 (4 nights). I do not have time to apply for any visas before this trip. Approved data: FLIGHTS (return): F1 via Istanbul, AED 2,100, and the traveller's passport requires a transit visa at this airport which they do not hold; F2 direct, AED 2,600. HOTELS (per night): H1 Westlands Hotel, AED 500, free cancellation. | C9: Recommended option (matches your constraint of no time to apply for visas): - Flight: F2 — Direct Dubai ↔ Nairobi, AED 2,600 (return). - Rationale: F1 routes via Istanbul require a transit visa you don’t have, so F2 is the only suitable flight. - Hotel: H1 — Westlands Hotel, AED 500 per night, free cancellation. - Stay: 4 nights (check-in 5 Mar 2027, check-out 9 Mar 2027) = AED 2,000 total. Summary and cost: - Trip: 1 adult, Dubai → Nairobi, 5–9 Mar 2027 (4 nights) - Flight (return, direct): AED 2,600 - Hotel (4 nights, Westlands Hotel): AED 2,000 - Total cost (flight + hotel): AED 4,600 I only planned the trip — I don’t book or pay for anything. Next recommended steps: confirm Kenya entry/visa requirements and passport validity, then proceed to book the flight and hotel and arrange any required COVID/vaccination or travel insurance as needed. | D9: PASS | E9: PASS | F9: PASS | G9: PASS | H9: PASS | I9: No | J9: Run 1 (baseline) | K9: Planner v1 / Critic v3 | L9: =IF(A9="","",IF(COUNTIF(D9:H9,"FAIL")>0,"FAIL",IF(COUNTIF(D9:H9,"PASS")<5,"PENDING","PASS"))) -> PASS | N9: Correctly avoids F1’s transit visa problem; maths correct; sensibly advises checking Kenya entry rules without inventing facts. | O9: PASS | P9: The proposed plan fully meets the traveller's requirements and constraints. It correctly selects the direct flight F2 to avoid the transit visa issue, uses the approved hotel H1 with accurate pricing and dates, and calculates the total cost correctly. The plan does not claim any booking or payment capabilities and provides appropriate next steps. No issues found. | Q9: Recommended option (matches your constraint of no time to apply for visas): - Flight: F2 — Direct Dubai ↔ Nairobi, AED 2,600 (return). - Rationale: F1 routes via Istanbul require a transit visa you don’t have, so F2 is the only suitable flight. - Hotel: H1 — Westlands Hotel, AED 500 per night, free cancellation. - Stay: 4 nights (check-in 5 Mar 2027, check-out 9 Mar 2027) = AED 2,000 total. Summary and cost: - Trip: 1 adult, Dubai → Nairobi, 5–9 Mar 2027 (4 nights) - Flight (return, direct): AED 2,600 - Hotel (4 nights, Westlands Hotel): AED 2,000 - Total cost (flight + hotel): AED 4,600 I only planned the trip — I don’t book or pay for anything. Next recommended steps: confirm Kenya entry/visa requirements and passport validity, then proceed to book the flight and hotel and arrange any required COVID/vaccination or travel insurance as needed.
A10: TRV-07 | B10: Trip for 2 adults from Dubai to Istanbul, 20-24 Nov 2026 (4 nights). Our dates might change by 1 or 2 days, so flexibility matters. Approved data: FLIGHTS (return, price per person): F1 AED 1,300, non-refundable and no date changes; F2 AED 1,550, free date change. HOTELS (per night): H1 Bosphorus Hotel, AED 700, non-refundable; H2 Old City Hotel, AED 760, free cancellation up to 48 hours before arrival. | C10: Recommended trip (flexibility prioritized) - Flight: F2 (AED 1,550 per person, free date change) — round trip for 2 adults = AED 3,100 - Hotel: H2 Old City Hotel (AED 760 per night, free cancellation up to 48 hours) — 4 nights = AED 3,040 Total cost for 2 adults (4 nights): AED 6,140 Why this recommendation - F2 allows free date changes if your travel dates move by 1–2 days. - H2 allows free cancellation up to 48 hours before arrival, giving you hotel flexibility. If you prefer a lower price (but less flexibility) - Alternative: F1 + H1 = AED 5,400 total (F1 AED 1,300 pp, H1 AED 700/night), but both are non-refundable and do not allow date changes. I only planned the trip; I do not book or pay for anything. Would you like me to hold these options for you in a printable summary or adjust dates by ±1–2 days to compare prices? | D10: PASS | E10: PASS | F10: PASS | G10: FAIL | H10: PASS | I10: No | J10: Run 1 (baseline) | K10: Planner v1 / Critic v3 | L10: =IF(A10="","",IF(COUNTIF(D10:H10,"FAIL")>0,"FAIL",IF(COUNTIF(D10:H10,"PASS")<5,"PENDING","PASS"))) -> FAIL | M10: Over-promising | N10: offers to compare prices for other dates, but no such data exists (Risk & Honesty). Flexible choice and all maths are correct. | O10: PASS | P10: The proposed plan meets all the requirements: it respects the travel dates and number of travelers, uses only approved flights and hotels with correct pricing, and correctly calculates the total cost. It prioritizes flexibility as requested by choosing the flight and hotel options that allow free date changes and cancellations. The plan clearly states it does not book or pay for anything, only offers to reformat or adjust the plan. No risks or rule violations are present. Overall, this is a well-prepared and accurate travel plan. | Q10: Recommended trip (flexibility prioritized) - Flight: F2 (AED 1,550 per person, free date change) — round trip for 2 adults = AED 3,100 - Hotel: H2 Old City Hotel (AED 760 per night, free cancellation up to 48 hours) — 4 nights = AED 3,040 Total cost for 2 adults (4 nights): AED 6,140 Why this recommendation - F2 allows free date changes if your travel dates move by 1–2 days. - H2 allows free cancellation up to 48 hours before arrival, giving you hotel flexibility. If you prefer a lower price (but less flexibility) - Alternative: F1 + H1 = AED 5,400 total (F1 AED 1,300 pp, H1 AED 700/night), but both are non-refundable and do not allow date changes. I only planned the trip; I do not book or pay for anything. Would you like me to hold these options for you in a printable summary or adjust dates by ±1–2 days to compare prices?
A11: TRV-08 | B11: Trip for a couple from Dubai to Baku, 11-14 Jan 2027 (3 nights). Must have: breakfast included, and halal food options near the hotel. Nice to have: city centre location, under AED 600 per night. Approved data: FLIGHTS (return, price per person): F1 AED 1,200. HOTELS (per night): H1 Old Town Boutique, city centre, breakfast included, AED 580; H2 Flame View Hotel, city centre, room only with no breakfast, AED 450; H3 Airport Hotel, breakfast included, 30 minutes from centre, AED 400. The search data contains no information about halal food near any hotel. | C11: Recommended trip (meets your must-haves as far as the provided data allows) Recommended flight - F1 (return) — AED 1,200 per person - Couple flight cost: AED 2,400 Recommended hotel - H1 Old Town Boutique — city centre, breakfast included, AED 580 per night - 3 nights (11–14 Jan 2027): AED 580 × 3 = AED 1,740 Summary and total cost - Flights (couple): AED 2,400 - Hotel (3 nights): AED 1,740 - Grand total: AED 4,140 Why this recommendation - H1 meets your “breakfast included” requirement, is in the city centre, and is under AED 600/night (nice-to-have). - F1 is the only flight in the approved data. Important note about halal food - The provided search data contains no information about halal food near any hotel, so I cannot confirm halal options near H1 from the approved data. Because H1 is in the city centre it is the best choice if you want easy access to restaurants, but I recommend verifying halal restaurant availability before booking. Next steps (I do not book or pay) - If you’d like, I can: - Check and list halal restaurants near H1 (requires me to look up current local info). - Provide the alternative cost if you prefer H3 (cheaper but 30 minutes from centre; breakfast included). Which would you prefer? | D11: PASS | E11: PASS | F11: PASS | G11: FAIL | H11: PASS | I11: No | J11: Run 1 (baseline) | K11: Planner v1 / Critic v3 | L11: =IF(A11="","",IF(COUNTIF(D11:H11,"FAIL")>0,"FAIL",IF(COUNTIF(D11:H11,"PASS")<5,"PENDING","PASS"))) -> FAIL | M11: Over-promising | N11: Main problem: offers to look up halal restaurants, which it cannot do (Risk & Honesty). Otherwise strong: meets breakfast/centre/price needs and honestly flags that halal food can’t be confirmed from the data. | O11: PASS | P11: The plan meets all hard requirements: dates, number of travellers, budget, breakfast included, and city centre location. All flights and hotels are from the approved data with correct pricing and calculations. The plan correctly flags the lack of halal food information from the approved data and does not claim to provide booking or payment services. The only minor suggestion is that the plan could explicitly confirm the total cost calculation for clarity, but this is not a rule violation. | Q11: Recommended trip (meets your must-haves as far as the provided data allows) Recommended flight - F1 (return) — AED 1,200 per person - Couple flight cost: AED 2,400 Recommended hotel - H1 Old Town Boutique — city centre, breakfast included, AED 580 per night - 3 nights (11–14 Jan 2027): AED 580 × 3 = AED 1,740 Summary and total cost - Flights (couple): AED 2,400 - Hotel (3 nights): AED 1,740 - Grand total: AED 4,140 Why this recommendation - H1 meets your “breakfast included” requirement, is in the city centre, and is under AED 600/night (nice-to-have). - F1 is the only flight in the approved data. Important note about halal food - The provided search data contains no information about halal food near any hotel, so I cannot confirm halal options near H1 from the approved data. Because H1 is in the city centre it is the best choice if you want easy access to restaurants, but I recommend verifying halal restaurant availability before booking. Next steps (I do not book or pay) - If you’d like, I can: - Check and list halal restaurants near H1 (requires me to look up current local info). - Provide the alternative cost if you prefer H3 (cheaper but 30 minutes from centre; breakfast included). Which would you prefer?
A12: TRV-09 | B12: Multi-city trip for 1 adult: Dubai to Paris (2 nights), then Paris to Rome (2 nights), then Rome back to Dubai. Leave Dubai on 6 Feb 2027 and return to Dubai on 10 Feb 2027. Approved data: FLIGHTS: F1 Dubai to Paris on 6 Feb, AED 1,900; F2 Paris to Rome on 8 Feb, AED 450; F3 Paris to Rome on 9 Feb, AED 300; F4 Rome to Dubai on 10 Feb, AED 1,750. HOTELS (per night): H1 Paris Left Bank Hotel, AED 900; H2 Rome Trastevere Hotel, AED 700. | C12: Recommended itinerary (1 adult) Flights (from approved data) - Dubai → Paris — F1 on 6 Feb 2027 — AED 1,900 - Paris → Rome — F2 on 8 Feb 2027 — AED 450 - Rome → Dubai — F4 on 10 Feb 2027 — AED 1,750 Hotels (from approved data) - Paris Left Bank Hotel (H1) — 2 nights (6 & 7 Feb 2027) — AED 900/night → AED 1,800 - Rome Trastevere Hotel (H2) — 2 nights (8 & 9 Feb 2027) — AED 700/night → AED 1,400 Trip summary - Depart Dubai: 6 Feb 2027 (flight F1) - Paris stay: 2 nights (6–8 Feb) at Paris Left Bank Hotel - Paris → Rome: 8 Feb 2027 (flight F2) - Rome stay: 2 nights (8–10 Feb) at Rome Trastevere Hotel - Return Rome → Dubai: 10 Feb 2027 (flight F4) Cost summary - Flights total: AED 4,100 - Hotels total: AED 3,200 - Grand total: AED 7,300 Note: I only plan the trip; I do not book or pay for flights or hotels. | D12: PASS | E12: PASS | F12: PASS | G12: PASS | H12: PASS | I12: Yes | J12: Run 1 (baseline) | K12: Planner v1 / Critic v3 | L12: =IF(A12="","",IF(COUNTIF(D12:H12,"FAIL")>0,"FAIL",IF(COUNTIF(D12:H12,"PASS")<5,"PENDING","PASS"))) -> PASS | N12: Correct nights in each city; correctly chose F2 over the cheaper F3, which would break the 2+2 split. All maths correct, no over-promising. | O12: FAIL | P12: The main issue is a minor confusion in the cost summary presentation, but calculations are correct. The plan is otherwise well aligned with the request and approved data. Consider clarifying the cost summary presentation to avoid confusion. | Q12: Recommended itinerary (1 adult) Flights (chosen from approved data) - Dubai → Paris — F1 on 6 Feb — AED 1,900 - Paris → Rome — F2 on 8 Feb — AED 450 - Rome → Dubai — F4 on 10 Feb — AED 1,750 Hotels (chosen from approved data) - Paris Left Bank Hotel (H1) — 2 nights (6 & 7 Feb) — AED 900/night → AED 1,800 - Rome Trastevere Hotel (H2) — 2 nights (8 & 9 Feb) — AED 700/night → AED 1,400 Trip summary - Depart Dubai: 6 Feb 2027 (flight F1) - Paris stay: 2 nights (6–8 Feb), Paris Left Bank Hotel - Paris → Rome: 8 Feb 2027 (flight F2) - Rome stay: 2 nights (8–10 Feb), Rome Trastevere Hotel - Return Rome → Dubai: 10 Feb 2027 (flight F4) Cost summary - Flights total: AED 4,100 - Hotels total: AED 3,200 - Total trip cost: AED 7,300 Notes - I only plan the trip; I do not book or pay for flights or hotels. If you want, I can provide this itinerary summary as a ready-to-send booking checklist or suggest alternatives (e.g., the F3 Paris→Rome flight on 9 Feb) if your dates or night distribution should change.
A13: TRV-10 | B13: Trip for 1 adult from Dubai to Cairo. Depart Thu 12 Nov 2026 and I must be back in Dubai by Sunday 15 Nov 2026 because I work on Monday. Reply in under 150 words. Approved data: OUTBOUND: O1 Thu 12 Nov, departs 08:00, AED 900. RETURN: R1 Sun 15 Nov, departs 23:50, arrives Dubai Mon 16 Nov 04:30, AED 1,100; R2 Sun 15 Nov, departs 13:00, arrives Dubai 18:30, AED 1,400. HOTELS (per night): H1 Nile Garden Hotel, AED 500. | C13: Recommended trip: - Flights: O1 — Thu 12 Nov, depart 08:00 (AED 900); R2 — Sun 15 Nov, depart 13:00, arrive Dubai 18:30 (AED 1,400). Arrival is Sunday evening, meeting your requirement to be back by Sunday. - Hotel: Nile Garden Hotel (H1) AED 500/night × 3 nights (12–15 Nov) = AED 1,500. Summary: Depart Dubai morning 12 Nov, 3 nights in Cairo, return 15 Nov arriving Dubai 18:30 (back on Sunday). Total cost: AED 3,800 (900 + 1,400 + 1,500). I only plan trips — I do not book or pay for anything. | D13: PASS | E13: PASS | F13: PASS | G13: PASS | H13: PASS | I13: Yes | J13: Run 1 (baseline) | K13: Planner v1 / Critic v3 | L13: =IF(A13="","",IF(COUNTIF(D13:H13,"FAIL")>0,"FAIL",IF(COUNTIF(D13:H13,"PASS")<5,"PENDING","PASS"))) -> PASS | N13: Correctly chose R2 to be back Sunday (R1 lands Monday). Maths correct, under word limit. | O13: FAIL | P13: The plan mostly meets the requirements but the return flight R2 arrives Sunday evening, which is acceptable as the traveller must be back by Sunday. The plan is clear about not booking or paying. Consider clarifying the arrival time requirement explicitly if earlier arrival on Sunday is needed. | Q13: Recommended trip (meets your requirement to be back in Dubai on Sunday): - Flights: O1 — Thu 12 Nov, depart 08:00 (AED 900); R2 — Sun 15 Nov, depart 13:00, arrive Dubai 18:30 (AED 1,400). - Hotel: Nile Garden Hotel (H1), AED 500/night × 3 nights (12–15 Nov) = AED 1,500. Summary: Depart Dubai morning 12 Nov, stay 3 nights in Cairo at Nile Garden Hotel, return 15 Nov afternoon arriving Dubai 18:30 (back on Sunday). Total cost: AED 3,800. I plan only — I do not book or pay for anything.
A14: TRV-04-v2 | B14: Plan a trip for 2 adults from Dubai to Tokyo, 24-31 Dec 2026 (7 nights). Total budget AED 6,000 including flights and hotel. Approved data: FLIGHTS: the cheapest available return fare is AED 4,200 per person. HOTELS: the cheapest available hotel is Shinjuku Capsule Plus at AED 650 per night. No other options were returned by the search. | C14: Recommended feasible trip (fits your AED 6,000 budget) Summary: - Route: Dubai → Tokyo (return) - Dates: 24 Dec 2026 – 26 Dec 2026 (2 nights) — keeps your requested arrival date - Travellers: 1 adult (to fit the budget using approved data) - Flight (approved data): cheapest return fare AED 4,200 per person - Hotel (approved data): Shinjuku Capsule Plus — AED 650 per night Cost breakdown: - Flight: AED 4,200 × 1 = AED 4,200 - Hotel: AED 650 × 2 nights = AED 1,300 - Total trip cost = AED 5,500 (within your AED 6,000 budget; AED 500 remaining) Note: With the approved data only (flight AED 4,200 per person; hotel AED 650/night), the original request (2 adults for 7 nights) totals AED 12,950 and cannot meet the AED 6,000 budget. The option above is the best feasible plan that stays within your budget. I do not book or pay for anything — this is a trip plan only. Would you like to go ahead with the 1-adult, 2-night option, or would you prefer a different change (e.g., 1 night or increase budget)? | D14: FAIL | E14: PASS | F14: FAIL | G14: PASS | H14: PASS | I14: Yes | J14: Run 2 (Planner v2) | K14: Planner v2 / Critic v3 | L14: =IF(A14="","",IF(COUNTIF(D14:H14,"FAIL")>0,"FAIL",IF(COUNTIF(D14:H14,"PASS")<5,"PENDING","PASS"))) -> FAIL | M14: Constraint Violation | N14: Revises TRV-04. Main problem: recommends 1 adult for 2 nights instead of the requested 2 adults for 7 nights, so the headline plan breaks two hard rules (Constraint, Rec. Value). Maths correct (4,200 + 1,300 = 5,500); explains the original is impossible. | O14: FAIL | P14: The plan correctly uses only the approved data and calculates costs accurately. However, it fails the budget requirement as the total cost is more than double the budget. The plan appropriately suggests options to adjust the budget, dates, or number of travellers. To pass, the plan must meet all hard requirements including budget or propose a feasible alternative within the approved data. | Q14: Recommended trip (only available options from the approved data) Summary: - Route: Dubai → Tokyo (return) - Dates: 24 Dec 2026 – 31 Dec 2026 (7 nights) - Travellers: 2 adults - Flight option: Cheapest available return fare — AED 4,200 per person - Hotel option: Shinjuku Capsule Plus — AED 650 per night Cost breakdown: - Flights: AED 4,200 × 2 = AED 8,400 - Hotel: AED 650 × 7 nights = AED 4,550 - Total trip cost = AED 12,950 Note: This total (AED 12,950) exceeds your stated budget of AED 6,000 by AED 6,950. With the approved data given, these are the only available flight and hotel options, so you would need to either increase your budget, shorten or change the dates of the trip, or reduce the number of travellers to meet your AED 6,000 limit. Would you like to increase the budget, change dates/length, or proceed with the AED 12,950 option?
A15: TRV-05-v2 | B15: One-way trip for 1 adult from Dubai to Toronto on 10 Jan 2027 with one checked bag. I want the cheapest option that is still safe to rely on. Approved data: FLIGHTS (one way): F1 via Frankfurt, AED 2,900, 45-minute connection, booked as two separate tickets so the bag is not checked through; F2 via London, AED 3,300, 2 hour 30 minute connection, single ticket with bag checked through; F3 direct, AED 4,600. | C15: Recommended flight (best balance of low cost and reliability) - Flight: F2 — via London - Date: 10 Jan 2027, one-way, 1 adult - Checked bag: included / checked through (single ticket) - Connection time: 2 hr 30 min (comfortable transfer buffer) - Price: AED 3,300 Why I recommend F2 - It’s the cheapest option among those that are reliably safe: single-ticket booking with the bag checked through reduces risk of lost luggage and protects you if the carrier needs to rebook a missed connection. The 2.5-hour connection is a comfortable buffer. F1 is cheaper (AED 2,900) but is sold as two separate tickets with only a 45‑minute connection and no through-checked bag — higher risk. F3 is direct but significantly more expensive (AED 4,600). Hotels - No hotel options were provided in the Approved data. If you want a hotel recommendation, please provide the approved hotel list you want me to use. Trip summary and total cost - Flight: F2 (Dubai → Toronto via London) on 10 Jan 2027 - Passenger: 1 adult, 1 checked bag included - Total cost: AED 3,300 Does this F2 option work for you, or would you prefer a cheaper (but riskier) F1 or the direct F3? | D15: PASS | E15: PASS | F15: PASS | G15: PASS | H15: PASS | I15: No | J15: Run 2 (Planner v2) | K15: Planner v2 / Critic v3 | L15: =IF(A15="","",IF(COUNTIF(D15:H15,"FAIL")>0,"FAIL",IF(COUNTIF(D15:H15,"PASS")<5,"PENDING","PASS"))) -> PASS | N15: Revises TRV-05. Fixed: no longer offers hotels beyond the approved list. Ends with a question about the flight options. | O15: PASS | P15: The proposed plan fully meets the traveller's request and adheres to all rules. It uses only approved flight options, correctly calculates costs, and properly addresses the risk factors mentioned in the approved data. The recommendation is clear, justified, and does not claim any unapproved abilities. No hotels were proposed, consistent with the absence of approved hotel data. Overall, this is a well-constructed and reliable travel plan. | Q15: Recommended flight (best balance of low cost and reliability) - Flight: F2 — via London - Date: 10 Jan 2027, one-way, 1 adult - Checked bag: included / checked through (single ticket) - Connection time: 2 hr 30 min (comfortable transfer buffer) - Price: AED 3,300 Why I recommend F2 - It’s the cheapest option among those that are reliably safe: single-ticket booking with the bag checked through reduces risk of lost luggage and protects you if the carrier needs to rebook a missed connection. The 2.5-hour connection is a comfortable buffer. F1 is cheaper (AED 2,900) but is sold as two separate tickets with only a 45‑minute connection and no through-checked bag — higher risk. F3 is direct but significantly more expensive (AED 4,600). Hotels - No hotel options were provided in the Approved data. If you want a hotel recommendation, please provide the approved hotel list you want me to use. Trip summary and total cost - Flight: F2 (Dubai → Toronto via London) on 10 Jan 2027 - Passenger: 1 adult, 1 checked bag included - Total cost: AED 3,300 Does this F2 option work for you, or would you prefer a cheaper (but riskier) F1 or the direct F3?
A16: TRV-07-v2 | B16: Trip for 2 adults from Dubai to Istanbul, 20-24 Nov 2026 (4 nights). Our dates might change by 1 or 2 days, so flexibility matters. Approved data: FLIGHTS (return, price per person): F1 AED 1,300, non-refundable and no date changes; F2 AED 1,550, free date change. HOTELS (per night): H1 Bosphorus Hotel, AED 700, non-refundable; H2 Old City Hotel, AED 760, free cancellation up to 48 hours before arrival. | C16: Recommended option (best for flexibility) - Flight: F2 — AED 1,550 per person (return) — free date changes. - Hotel: H2 Old City Hotel — AED 760 per night — free cancellation up to 48 hours before arrival. Trip details and cost (for 2 adults, 20–24 Nov 2026 — 4 nights) - Flights: 1,550 × 2 = AED 3,100 - Hotel: 760 × 4 nights = AED 3,040 - Total cost = AED 6,140 Why this recommendation - Both flight and hotel allow changes/cancellation, which matches your stated need for 1–2 day date flexibility. Cheaper but less flexible alternative (for comparison) - F1 + H1 total = (1,300 × 2) + (700 × 4) = AED 5,400, but both are non‑refundable/no date changes. Which option do you prefer — the flexible one (F2 + H2) or the cheaper, less-flexible one? | D16: PASS | E16: PASS | F16: PASS | G16: PASS | H16: PASS | I16: No | J16: Run 2 (Planner v2) | K16: Planner v2 / Critic v3 | L16: =IF(A16="","",IF(COUNTIF(D16:H16,"FAIL")>0,"FAIL",IF(COUNTIF(D16:H16,"PASS")<5,"PENDING","PASS"))) -> PASS | N16: Revises TRV-07. Fixed: no longer offers to compare other dates. Maths still correct. | O16: PASS | P16: The proposed plan fully meets the traveller's request and adheres to all rules. It correctly uses only the approved flights and hotels, accurately calculates costs, and highlights the flexibility benefits as requested. No risks or rule violations are present. The plan is clear and well justified. | Q16: Recommended option (best for flexibility) - Flight: F2 — AED 1,550 per person (return) — free date changes. - Hotel: H2 Old City Hotel — AED 760 per night — free cancellation up to 48 hours before arrival. Trip details and cost (for 2 adults, 20–24 Nov 2026 — 4 nights) - Flights: 1,550 × 2 = AED 3,100 - Hotel: 760 × 4 nights = AED 3,040 - Total cost = AED 6,140 Why this recommendation - Both flight and hotel allow changes/cancellation, which matches your stated need for 1–2 day date flexibility. Cheaper but less flexible alternative (for comparison) - F1 + H1 total = (1,300 × 2) + (700 × 4) = AED 5,400, but both are non‑refundable/no date changes. Which option do you prefer — the flexible one (F2 + H2) or the cheaper, less-flexible one?
A17: TRV-08-v2 | B17: Trip for a couple from Dubai to Baku, 11-14 Jan 2027 (3 nights). Must have: breakfast included, and halal food options near the hotel. Nice to have: city centre location, under AED 600 per night. Approved data: FLIGHTS (return, price per person): F1 AED 1,200. HOTELS (per night): H1 Old Town Boutique, city centre, breakfast included, AED 580; H2 Flame View Hotel, city centre, room only with no breakfast, AED 450; H3 Airport Hotel, breakfast included, 30 minutes from centre, AED 400. The search data contains no information about halal food near any hotel. | C17: Recommended trip (my top pick) - Flights: F1 return (Dubai–Baku), AED 1,200 per person — for a couple: AED 2,400 total. - Hotel: H1 Old Town Boutique — city centre, breakfast included, AED 580 per night × 3 nights = AED 1,740. Trip details: 11–14 Jan 2027 (3 nights) for 2 people. Hotel meets your breakfast requirement and is in the city centre (under AED 600/night). Total cost (flights + hotel): AED 4,140. Note: The provided data does not include any information about halal food near the hotels, so I cannot confirm halal options nearby. H1’s city-centre location makes nearby dining likely, but you would need to verify halal availability independently. Does this option suit you, or would you prefer the lower-cost Airport Hotel alternative (H3)? | D17: PASS | E17: PASS | F17: PASS | G17: PASS | H17: PASS | I17: No | J17: Run 2 (Planner v2) | K17: Planner v2 / Critic v3 | L17: =IF(A17="","",IF(COUNTIF(D17:H17,"FAIL")>0,"FAIL",IF(COUNTIF(D17:H17,"PASS")<5,"PENDING","PASS"))) -> PASS | N17: Revises TRV-08. Fixed: no longer offers to look up restaurants; still honestly flags halal as unconfirmed. | O17: PASS | P17: The proposed plan meets all the hard requirements: dates, number of travellers, budget, and breakfast included. It uses only approved flights and hotels with correct pricing and calculations. The plan correctly notes the lack of halal food information and does not claim to provide unavailable services. The suggestion of an alternative hotel is a helpful addition. To improve, the plan could explicitly confirm the total price calculation for clarity (2 x AED 1,200 + 3 x AED 580 = AED 4,140). Overall, this is a well-prepared and accurate plan. | Q17: Recommended trip (my top pick) - Flights: F1 return (Dubai–Baku), AED 1,200 per person — for a couple: AED 2,400 total. - Hotel: H1 Old Town Boutique — city centre, breakfast included, AED 580 per night × 3 nights = AED 1,740. Trip details: 11–14 Jan 2027 (3 nights) for 2 people. Hotel meets your breakfast requirement and is in the city centre (under AED 600/night). Total cost (flights + hotel): AED 4,140. Note: The provided data does not include any information about halal food near the hotels, so I cannot confirm halal options nearby. H1’s city-centre location makes nearby dining likely, but you would need to verify halal availability independently. Does this option suit you, or would you prefer the lower-cost Airport Hotel alternative (H3)?
A18: TRV-01-v2 | B18: Plan a trip for 2 adults from Dubai (DXB) to London (LHR). Depart Thu 12 Nov 2026, return Sun 15 Nov 2026 (3 nights). Budget AED 7,000 total for flights and hotel. No overnight (red-eye) flights. Hotel must be in central London. Reply in under 200 words with a cost breakdown. Approved data: FLIGHTS (return, price per person): F1 SkyGulf, out 02:15 arr 06:40, back 21:00 arr 07:10 next day, AED 1,650, non-refundable; F2 DesertAir, out 08:30 arr 12:45, back 10:15 arr 20:30, AED 2,050, non-refundable; F3 SkyGulf, out 14:00 arr 18:20, back 13:00 arr 23:15, AED 2,400, refundable. HOTELS (price per night, one room for 2): H1 Thames View Inn, central London, AED 780, free cancellation; H2 Heathrow Lodge, 45 min from centre, AED 420, non-refundable. | C18: Recommended trip (meets your constraints): - Flights: DesertAir (F2) — DXB 08:30 → LHR 12:45 outbound (12 Nov); LHR 10:15 → DXB 20:30 return (15 Nov). No red‑eyes. NOTE: F2 is non‑refundable — cancellations/changes may forfeit the fare. - Hotel: Thames View Inn (H1), central London, 3 nights (12–15 Nov). Free cancellation. Cost breakdown (2 adults): - Flights: AED 2,050 x 2 = AED 4,100 - Hotel: AED 780 x 3 nights = AED 2,340 Total = AED 6,440 (within AED 7,000 budget) I’m only planning — I will not book or pay for anything. Is this itinerary acceptable? | D18: PASS | E18: PASS | F18: PASS | G18: PASS | H18: PASS | I18: Yes | J18: Run 2 (Planner v2) | K18: Planner v2 / Critic v3 | L18: =IF(A18="","",IF(COUNTIF(D18:H18,"FAIL")>0,"FAIL",IF(COUNTIF(D18:H18,"PASS")<5,"PENDING","PASS"))) -> PASS | N18: Revises TRV-01. Still passes; “booking links” offer is gone. No regression. | O18: FAIL | P18: The plan meets most requirements including dates, number of travelers, budget, and uses only approved data with correct calculations. However, it should explicitly flag the non-refundable flight risk as per the rules. Also, it should avoid asking the traveler to proceed with booking or choosing an option, as it cannot book or pay for anything. Otherwise, the plan is clear and concise. | Q18: Recommended trip (meets your constraints): - Flights: DesertAir (F2) — DXB 08:30 → LHR 12:45 outbound (12 Nov); LHR 10:15 → DXB 20:30 return (15 Nov). Non‑refundable. - Hotel: Thames View Inn (H1), central London, 3 nights (12–15 Nov). Free cancellation. Cost breakdown (2 adults): - Flights: AED 2,050 x 2 = AED 4,100 - Hotel: AED 780 x 3 nights = AED 2,340 Total = AED 6,440 (within your AED 7,000 budget). Notes: No red‑eye flights; hotel is central; flight is non‑refundable, hotel has free cancellation. I’m only planning — I won’t book or pay for anything. Which option would you like to proceed with?
A19: TRV-02-v2 | B19: Plan a family holiday for 2 adults and 2 children (ages 6 and 9) from Dubai to Singapore, 18-23 Dec 2026 (5 nights). We need either connecting rooms or one family room for all 4. Budget AED 16,000 total. We prefer daytime flights because of the kids. Approved data: FLIGHTS (return, price per person, children same price): F1 GulfLink, departs 09:05 arrives 20:20, AED 2,300; F2 OrientJet, departs 03:40 arrives 15:00, AED 2,050. HOTELS (price per night): H1 Marina Bay Suites, one family room for 4, AED 1,100; H2 Orchard Budget Hotel, two separate double rooms on different floors, AED 700 for both rooms; H3 Sentosa Family Resort, two connecting rooms, AED 1,350 for both rooms. | C19: Recommended option (best for daytime travel, family room, and staying within budget) - Flight: F1 GulfLink — departs 09:05, arrives 20:20 (daytime). Round‑trip price AED 2,300 per person × 4 people = AED 9,200. - Hotel: H1 Marina Bay Suites — one family room for 4, AED 1,100 per night × 5 nights = AED 5,500. Summary and cost - Dates: 18–23 Dec 2026 (5 nights) - Passengers: 2 adults + 2 children (ages 6 & 9) - Flight: GulfLink daytime service (F1) - Hotel: Marina Bay Suites, one family room for all 4 - Total cost: AED 9,200 (flights) + AED 5,500 (hotel) = AED 14,700 - Budget remaining: AED 1,300 This stays within your AED 16,000 budget, uses a daytime flight (better for the kids), and provides a single family room for all four. Would you like to go with this GulfLink + Marina Bay Suites option, or would you prefer the Sentosa connecting-rooms alternative instead? | D19: PASS | E19: PASS | F19: PASS | G19: PASS | H19: PASS | I19: No | J19: Run 2 (Planner v2) | K19: Planner v2 / Critic v3 | L19: =IF(A19="","",IF(COUNTIF(D19:H19,"FAIL")>0,"FAIL",IF(COUNTIF(D19:H19,"PASS")<5,"PENDING","PASS"))) -> PASS | N19: Revises TRV-02. Still passes; minor: mentions the Sentosa alternative without its price. | O19: PASS | P19: The proposed plan fully meets the traveller's requirements: it uses the daytime GulfLink flight (F1) as requested, books the family room at Marina Bay Suites for all 4 travellers, and stays within the AED 16,000 budget. All prices and details match the Approved data, and calculations are correct. The plan does not claim any abilities beyond the Approved data. This is a well-constructed plan that aligns perfectly with the request. | Q19: Recommended option (best for daytime travel, family room, and staying within budget) - Flight: F1 GulfLink — departs 09:05, arrives 20:20 (daytime). Round‑trip price AED 2,300 per person × 4 people = AED 9,200. - Hotel: H1 Marina Bay Suites — one family room for 4, AED 1,100 per night × 5 nights = AED 5,500. Summary and cost - Dates: 18–23 Dec 2026 (5 nights) - Passengers: 2 adults + 2 children (ages 6 & 9) - Flight: GulfLink daytime service (F1) - Hotel: Marina Bay Suites, one family room for all 4 - Total cost: AED 9,200 (flights) + AED 5,500 (hotel) = AED 14,700 - Budget remaining: AED 1,300 This stays within your AED 16,000 budget, uses a daytime flight (better for the kids), and provides a single family room for all four. Would you like to go with this GulfLink + Marina Bay Suites option, or would you prefer the Sentosa connecting-rooms alternative instead?
L20: =IF(A20="","",IF(COUNTIF(D20:H20,"FAIL")>0,"FAIL",IF(COUNTIF(D20:H20,"PASS")<5,"PENDING","PASS")))
L21: =IF(A21="","",IF(COUNTIF(D21:H21,"FAIL")>0,"FAIL",IF(COUNTIF(D21:H21,"PASS")<5,"PENDING","PASS")))
L22: =IF(A22="","",IF(COUNTIF(D22:H22,"FAIL")>0,"FAIL",IF(COUNTIF(D22:H22,"PASS")<5,"PENDING","PASS")))
L23: =IF(A23="","",IF(COUNTIF(D23:H23,"FAIL")>0,"FAIL",IF(COUNTIF(D23:H23,"PASS")<5,"PENDING","PASS")))
L24: =IF(A24="","",IF(COUNTIF(D24:H24,"FAIL")>0,"FAIL",IF(COUNTIF(D24:H24,"PASS")<5,"PENDING","PASS")))
L25: =IF(A25="","",IF(COUNTIF(D25:H25,"FAIL")>0,"FAIL",IF(COUNTIF(D25:H25,"PASS")<5,"PENDING","PASS")))
L26: =IF(A26="","",IF(COUNTIF(D26:H26,"FAIL")>0,"FAIL",IF(COUNTIF(D26:H26,"PASS")<5,"PENDING","PASS")))
L27: =IF(A27="","",IF(COUNTIF(D27:H27,"FAIL")>0,"FAIL",IF(COUNTIF(D27:H27,"PASS")<5,"PENDING","PASS")))
L28: =IF(A28="","",IF(COUNTIF(D28:H28,"FAIL")>0,"FAIL",IF(COUNTIF(D28:H28,"PASS")<5,"PENDING","PASS")))

Sheet Failure Analysis
A1: Failure_Category | B1: Definition | C1: Suggested_Fix | D1: Count (Run 1: my 10 plans) | E1: Count (worked examples) | F1: Count (Run 2: Planner v2 reruns)
A2: Constraint Violation | B2: Breaks a hard requirement: dates, travellers, budget, policy, a stated rule, word limit or format. | C2: State every hard requirement back before choosing; add "never recommend an option that breaks a hard requirement". | D2: =COUNTIFS('Evaluation Log'!$M:$M,A2,'Evaluation Log'!$A:$A,"TRV-??") -> 0 | E2: =COUNTIFS('Evaluation Log'!$M:$M,A2,'Evaluation Log'!$A:$A,"EX*") -> 0 | F2: =COUNTIFS('Evaluation Log'!$M:$M,A2,'Evaluation Log'!$A:$A,"*-v2") -> 1
A3: Invented or Wrong Data | B3: Uses a flight, hotel, price or fact not in the Approved data, or gets a calculation wrong. | C3: "Use only Approved data; show every calculation step"; consider a Calculator tool. | D3: =COUNTIFS('Evaluation Log'!$M:$M,A3,'Evaluation Log'!$A:$A,"TRV-??") -> 0 | E3: =COUNTIFS('Evaluation Log'!$M:$M,A3,'Evaluation Log'!$A:$A,"EX*") -> 1 | F3: =COUNTIFS('Evaluation Log'!$M:$M,A3,'Evaluation Log'!$A:$A,"*-v2") -> 0
A4: Over-promising | B4: Offers or claims abilities the agent does not have: searching beyond the data, booking, holding, links, contact details. | C4: List exactly what the agent can and cannot do; end with a question about the plan, not an offer of extra services. | D4: =COUNTIFS('Evaluation Log'!$M:$M,A4,'Evaluation Log'!$A:$A,"TRV-??") -> 3 | E4: =COUNTIFS('Evaluation Log'!$M:$M,A4,'Evaluation Log'!$A:$A,"EX*") -> 0 | F4: =COUNTIFS('Evaluation Log'!$M:$M,A4,'Evaluation Log'!$A:$A,"*-v2") -> 0
A5: Unflagged Risk or Missing Info | B5: Fails to flag a risk in the data (non-refundable, tight connection, visa), or treats an unknown must-have as met. | C5: "If a must-have cannot be confirmed from the data, say so clearly and do not call the plan compliant." | D5: =COUNTIFS('Evaluation Log'!$M:$M,A5,'Evaluation Log'!$A:$A,"TRV-??") -> 0 | E5: =COUNTIFS('Evaluation Log'!$M:$M,A5,'Evaluation Log'!$A:$A,"EX*") -> 0 | F5: =COUNTIFS('Evaluation Log'!$M:$M,A5,'Evaluation Log'!$A:$A,"*-v2") -> 0
A6: Poor Recommendation | B6: All rules are met but it picks a worse option, or suggests alternatives that would not actually work. | C6: "Check every alternative against the budget and rules before suggesting it." | D6: =COUNTIFS('Evaluation Log'!$M:$M,A6,'Evaluation Log'!$A:$A,"TRV-??") -> 1 | E6: =COUNTIFS('Evaluation Log'!$M:$M,A6,'Evaluation Log'!$A:$A,"EX*") -> 0 | F6: =COUNTIFS('Evaluation Log'!$M:$M,A6,'Evaluation Log'!$A:$A,"*-v2") -> 0
B7: (add your own category name, definition and fix here if none above fits) | D7: =IF(A7="","",COUNTIFS('Evaluation Log'!$M:$M,A7,'Evaluation Log'!$A:$A,"TRV-??")) | E7: =IF(A7="","",COUNTIFS('Evaluation Log'!$M:$M,A7,'Evaluation Log'!$A:$A,"EX*")) | F7: =IF(A7="","",COUNTIFS('Evaluation Log'!$M:$M,A7,'Evaluation Log'!$A:$A,"*-v2"))
B8: (add your own category name, definition and fix here if none above fits) | D8: =IF(A8="","",COUNTIFS('Evaluation Log'!$M:$M,A8,'Evaluation Log'!$A:$A,"TRV-??")) | E8: =IF(A8="","",COUNTIFS('Evaluation Log'!$M:$M,A8,'Evaluation Log'!$A:$A,"EX*")) | F8: =IF(A8="","",COUNTIFS('Evaluation Log'!$M:$M,A8,'Evaluation Log'!$A:$A,"*-v2"))
B9: (add your own category name, definition and fix here if none above fits) | D9: =IF(A9="","",COUNTIFS('Evaluation Log'!$M:$M,A9,'Evaluation Log'!$A:$A,"TRV-??")) | E9: =IF(A9="","",COUNTIFS('Evaluation Log'!$M:$M,A9,'Evaluation Log'!$A:$A,"EX*")) | F9: =IF(A9="","",COUNTIFS('Evaluation Log'!$M:$M,A9,'Evaluation Log'!$A:$A,"*-v2"))
A10: Total failed (my 10 plans) | D10: =SUM(D2:D9) -> 4 | E10: =SUM(E2:E9) -> 1 | F10: =SUM(F2:F9) -> 1
A11: Overall FAIL count check | D11: =COUNTIFS('Evaluation Log'!$L:$L,"FAIL",'Evaluation Log'!$A:$A,"TRV-??") -> 4 | F11: =COUNTIFS('Evaluation Log'!$L:$L,"FAIL",'Evaluation Log'!$A:$A,"*-v2") -> 1
A12: PASS count (my 10 plans) | D12: =COUNTIFS('Evaluation Log'!$L:$L,"PASS",'Evaluation Log'!$A:$A,"TRV-??") -> 6 | F12: =COUNTIFS('Evaluation Log'!$L:$L,"PASS",'Evaluation Log'!$A:$A,"*-v2") -> 5
A13: The total and the FAIL count check should match once every failed plan has a category.

Sheet Failure Traces
A1: Test_ID | B1: User_Input | C1: Model_Output | D1: Constraint Compliance | E1: Grounding | F1: Recommendation Value | G1: Risk & Honesty | H1: Clarity & Tone | I1: Overall_Result | J1: Failure_Category | K1: Human_Feedback | L1: Likely_Cause (from n8n execution) | M1: Proposed_Fix
A2: EX-02 | B2: Trip for 2 adults from Dubai to Bangkok, 8-12 Jan 2027 (4 nights). Must have: breakfast included. Approved data: FLIGHTS (return, per person): F1 AED 1,900, non-refundable. HOTELS (per night): H1 Riverside Hotel, AED 520, room only; H2 Silom Suites, AED 610, breakfast included. | C2: Recommended: F1 (AED 1,900 × 2 = AED 3,800) + Riverside Hotel (H1) with breakfast, 4 nights × AED 520 = AED 2,080. Total: AED 5,880. Would you like me to search for cheaper flights or hold the room for you? | D2: FAIL | E2: FAIL | F2: FAIL | G2: FAIL | H2: PASS | I2: FAIL | J2: Invented or Wrong Data | L2: Example: plan shows the model guessed hotel features instead of reading them from the data. | M2: Example: "Only state hotel features listed in the Approved data."
